<?xml version="1.0" ?>
<sdf version="1.6">
  <world name="world">
    <model name="salamander">
      <pose>0.0 0.0 0.0 0.0 0.0 0.0</pose>
      <link name="link_body_0">
        <pose>0.0 0.0 0.0 0.0 0.0 0.0</pose>
        <inertial>
          <pose>0.006714263575088745 -1.960440964835103e-07 -1.371206419060886e-06 0.0 0.0 0.0</pose>
          <mass>0.00030133236332711153</mass>
          <inertia>
            <ixx>1.871392745404874e-09</ixx>
            <ixy>-1.580462968659555e-13</ixy>
            <ixz>2.595537477393151e-12</ixz>
            <iyy>3.441363919070135e-09</iyy>
            <iyz>1.1717730630065719e-13</iyz>
            <izz>3.76327339485108e-09</izz>
          </inertia>
        </inertial>
        <collision name="link_0_collision">
          <pose>0.0 0.0 0.0 0.0 0.0 0.0</pose>
          <geometry>
            <mesh>
              <uri>meshes_salamander/link_0.obj</uri>
              <scale>0.1 0.1 0.1</scale>
            </mesh>
          </geometry>
        </collision>
        <visual name="link_0_visual">
          <pose>0.0 0.0 0.0 0.0 0.0 0.0</pose>
          <geometry>
            <mesh>
              <uri>meshes_salamander/link_0.obj</uri>
              <scale>0.1 0.1 0.1</scale>
            </mesh>
          </geometry>
          <material>
            <ambient>0.1 0.7 0.1 1.0</ambient>
            <diffuse>0.1 0.7 0.1 1.0</diffuse>
            <specular>0.1 0.7 0.1 1.0</specular>
            <emissive>0.1 0.7 0.1 1.0</emissive>
          </material>
        </visual>
        <visual name="eye_left_visual">
          <pose>0.004 -0.003 0.0015 0.0 0.0 0.0</pose>
          <geometry>
            <sphere>
              <radius>0.001</radius>
            </sphere>
          </geometry>
          <material>
            <ambient>0.0 0.0 0.0 1.0</ambient>
            <diffuse>0.0 0.0 0.0 1.0</diffuse>
            <specular>0.0 0.0 0.0 1.0</specular>
            <emissive>0.0 0.0 0.0 1.0</emissive>
          </material>
        </visual>
        <visual name="eye_right_visual">
          <pose>0.004 0.003 0.0015 0.0 0.0 0.0</pose>
          <geometry>
            <sphere>
              <radius>0.001</radius>
            </sphere>
          </geometry>
          <material>
            <ambient>0.0 0.0 0.0 1.0</ambient>
            <diffuse>0.0 0.0 0.0 1.0</diffuse>
            <specular>0.0 0.0 0.0 1.0</specular>
            <emissive>0.0 0.0 0.0 1.0</emissive>
          </material>
        </visual>
      </link>
      <link name="link_body_1">
        <pose>0.015000000596046448 0.0 0.0 0.0 0.0 0.0</pose>
        <inertial>
          <pose>0.002220299492418204 -9.10891238377578e-07 8.627851573387512e-07 0.0 0.0 0.0</pose>
          <mass>0.00047672314163557265</mass>
          <inertia>
            <ixx>4.704344529910424e-09</ixx>
            <ixy>-2.5574259171123093e-13</ixy>
            <ixz>1.1674159359523158e-12</ixz>
            <iyy>6.530377982593764e-09</iyy>
            <iyz>-6.218596301748208e-13</iyz>
            <izz>7.427646096996682e-09</izz>
          </inertia>
        </inertial>
        <collision name="link_1_collision">
          <pose>0.0 0.0 0.0 0.0 0.0 0.0</pose>
          <geometry>
            <mesh>
              <uri>meshes_salamander/link_1.obj</uri>
              <scale>0.1 0.1 0.1</scale>
            </mesh>
          </geometry>
        </collision>
        <visual name="link_1_visual">
          <pose>0.0 0.0 0.0 0.0 0.0 0.0</pose>
          <geometry>
            <mesh>
              <uri>meshes_salamander/link_1.obj</uri>
              <scale>0.1 0.1 0.1</scale>
            </mesh>
          </geometry>
          <material>
            <ambient>0.06999999999999999 0.48999999999999994 0.06999999999999999 1.0</ambient>
            <diffuse>0.06999999999999999 0.48999999999999994 0.06999999999999999 1.0</diffuse>
            <specular>0.06999999999999999 0.48999999999999994 0.06999999999999999 1.0</specular>
            <emissive>0.06999999999999999 0.48999999999999994 0.06999999999999999 1.0</emissive>
          </material>
        </visual>
      </link>
      <link name="link_body_2">
        <pose>0.02571428716182709 0.0 0.0 0.0 0.0 0.0</pose>
        <inertial>
          <pose>0.0017968106358545559 1.336620445954096e-06 4.4264808275054773e-07 0.0 0.0 0.0</pose>
          <mass>0.0005975962731987004</mass>
          <inertia>
            <ixx>6.3573386233514856e-09</ixx>
            <ixy>-1.5872321051569855e-12</ixy>
            <ixz>-2.673802891263105e-12</ixz>
            <iyy>9.389179149860035e-09</iyy>
            <iyz>-1.7736360374768376e-13</iyz>
            <izz>1.0433443241321343e-08</izz>
          </inertia>
        </inertial>
        <collision name="link_2_collision">
          <pose>0.0 0.0 0.0 0.0 0.0 0.0</pose>
          <geometry>
            <mesh>
              <uri>meshes_salamander/link_2.obj</uri>
              <scale>0.1 0.1 0.1</scale>
            </mesh>
          </geometry>
        </collision>
        <visual name="link_2_visual">
          <pose>0.0 0.0 0.0 0.0 0.0 0.0</pose>
          <geometry>
            <mesh>
              <uri>meshes_salamander/link_2.obj</uri>
              <scale>0.1 0.1 0.1</scale>
            </mesh>
          </geometry>
          <material>
            <ambient>0.1 0.7 0.1 1.0</ambient>
            <diffuse>0.1 0.7 0.1 1.0</diffuse>
            <specular>0.1 0.7 0.1 1.0</specular>
            <emissive>0.1 0.7 0.1 1.0</emissive>
          </material>
        </visual>
      </link>
      <link name="link_body_3">
        <pose>0.03642857074737549 0.0 0.0 0.0 0.0 0.0</pose>
        <inertial>
          <pose>0.0021498116814032664 5.932256589600578e-07 -3.2742752553527933e-07 0.0 0.0 0.0</pose>
          <mass>0.0004700280027218766</mass>
          <inertia>
            <ixx>3.628310456626311e-09</ixx>
            <ixy>-3.9008625360486085e-13</ixy>
            <ixz>-2.0574068190527665e-12</ixz>
            <iyy>7.213461565878215e-09</iyy>
            <iyz>-7.54795992605657e-13</iyz>
            <izz>7.654095343951123e-09</izz>
          </inertia>
        </inertial>
        <collision name="link_3_collision">
          <pose>0.0 0.0 0.0 0.0 0.0 0.0</pose>
          <geometry>
            <mesh>
              <uri>meshes_salamander/link_3.obj</uri>
              <scale>0.1 0.1 0.1</scale>
            </mesh>
          </geometry>
        </collision>
        <visual name="link_3_visual">
          <pose>0.0 0.0 0.0 0.0 0.0 0.0</pose>
          <geometry>
            <mesh>
              <uri>meshes_salamander/link_3.obj</uri>
              <scale>0.1 0.1 0.1</scale>
            </mesh>
          </geometry>
          <material>
            <ambient>0.06999999999999999 0.48999999999999994 0.06999999999999999 1.0</ambient>
            <diffuse>0.06999999999999999 0.48999999999999994 0.06999999999999999 1.0</diffuse>
            <specular>0.06999999999999999 0.48999999999999994 0.06999999999999999 1.0</specular>
            <emissive>0.06999999999999999 0.48999999999999994 0.06999999999999999 1.0</emissive>
          </material>
        </visual>
      </link>
      <link name="link_body_4">
        <pose>0.04714285731315613 0.0 0.0 0.0 0.0 0.0</pose>
        <inertial>
          <pose>0.0030358143029494754 -2.4591814423833454e-07 2.0037478890438305e-06 0.0 0.0 0.0</pose>
          <mass>0.0002320604131992463</mass>
          <inertia>
            <ixx>9.476457794972613e-10</ixx>
            <ixy>-4.4850234545254333e-13</ixy>
            <ixz>-6.411879211692048e-13</ixz>
            <iyy>3.069675639027217e-09</iyy>
            <iyz>-1.1719858364671856e-12</iyz>
            <izz>2.960039747206307e-09</izz>
          </inertia>
        </inertial>
        <collision name="link_4_collision">
          <pose>0.0 0.0 0.0 0.0 0.0 0.0</pose>
          <geometry>
            <mesh>
              <uri>meshes_salamander/link_4.obj</uri>
              <scale>0.1 0.1 0.1</scale>
            </mesh>
          </geometry>
        </collision>
        <visual name="link_4_visual">
          <pose>0.0 0.0 0.0 0.0 0.0 0.0</pose>
          <geometry>
            <mesh>
              <uri>meshes_salamander/link_4.obj</uri>
              <scale>0.1 0.1 0.1</scale>
            </mesh>
          </geometry>
          <material>
            <ambient>0.1 0.7 0.1 1.0</ambient>
            <diffuse>0.1 0.7 0.1 1.0</diffuse>
            <specular>0.1 0.7 0.1 1.0</specular>
            <emissive>0.1 0.7 0.1 1.0</emissive>
          </material>
        </visual>
      </link>
      <link name="link_body_5">
        <pose>0.05785714387893677 0.0 0.0 0.0 0.0 0.0</pose>
        <inertial>
          <pose>0.0037639998035171826 1.0228943641398372e-07 1.43795662967751e-06 0.0 0.0 0.0</pose>
          <mass>0.00018695318327016324</mass>
          <inertia>
            <ixx>6.803177293479393e-10</ixx>
            <ixy>-1.8244898684009752e-13</ixy>
            <ixz>5.4126332555035076e-14</ixz>
            <iyy>2.396977652334704e-09</iyy>
            <iyz>-4.973977948992725e-14</iyz>
            <izz>2.1239303944779323e-09</izz>
          </inertia>
        </inertial>
        <collision name="link_5_collision">
          <pose>0.0 0.0 0.0 0.0 0.0 0.0</pose>
          <geometry>
            <mesh>
              <uri>meshes_salamander/link_5.obj</uri>
              <scale>0.1 0.1 0.1</scale>
            </mesh>
          </geometry>
        </collision>
        <visual name="link_5_visual">
          <pose>0.0 0.0 0.0 0.0 0.0 0.0</pose>
          <geometry>
            <mesh>
              <uri>meshes_salamander/link_5.obj</uri>
              <scale>0.1 0.1 0.1</scale>
            </mesh>
          </geometry>
          <material>
            <ambient>0.06999999999999999 0.48999999999999994 0.06999999999999999 1.0</ambient>
            <diffuse>0.06999999999999999 0.48999999999999994 0.06999999999999999 1.0</diffuse>
            <specular>0.06999999999999999 0.48999999999999994 0.06999999999999999 1.0</specular>
            <emissive>0.06999999999999999 0.48999999999999994 0.06999999999999999 1.0</emissive>
          </material>
        </visual>
      </link>
      <link name="link_body_6">
        <pose>0.0685714304447174 0.0 0.0 0.0 0.0 0.0</pose>
        <inertial>
          <pose>0.003930872660455469 -2.504626523218651e-07 -7.317062110898338e-07 0.0 0.0 0.0</pose>
          <mass>0.00014129535886692283</mass>
          <inertia>
            <ixx>4.5559250972119804e-10</ixx>
            <ixy>-2.1432233342400839e-13</ixy>
            <ixz>2.1668315641925428e-13</ixz>
            <iyy>1.8069601385778823e-09</iyy>
            <iyz>2.4379962172182226e-13</iyz>
            <izz>1.5260718041557112e-09</izz>
          </inertia>
        </inertial>
        <collision name="link_6_collision">
          <pose>0.0 0.0 0.0 0.0 0.0 0.0</pose>
          <geometry>
            <mesh>
              <uri>meshes_salamander/link_6.obj</uri>
              <scale>0.1 0.1 0.1</scale>
            </mesh>
          </geometry>
        </collision>
        <visual name="link_6_visual">
          <pose>0.0 0.0 0.0 0.0 0.0 0.0</pose>
          <geometry>
            <mesh>
              <uri>meshes_salamander/link_6.obj</uri>
              <scale>0.1 0.1 0.1</scale>
            </mesh>
          </geometry>
          <material>
            <ambient>0.1 0.7 0.1 1.0</ambient>
            <diffuse>0.1 0.7 0.1 1.0</diffuse>
            <specular>0.1 0.7 0.1 1.0</specular>
            <emissive>0.1 0.7 0.1 1.0</emissive>
          </material>
        </visual>
      </link>
      <link name="link_body_7">
        <pose>0.07928571701049805 0.0 0.0 0.0 0.0 0.0</pose>
        <inertial>
          <pose>0.004277215855732852 1.4231918064340268e-06 -3.804498897934417e-06 0.0 0.0 0.0</pose>
          <mass>0.00010409173814124655</mass>
          <inertia>
            <ixx>2.9803750476599033e-10</ixx>
            <ixy>1.3218380674003593e-13</ixy>
            <ixz>2.4143982548428853e-13</ixz>
            <iyy>1.2829293383985688e-09</iyy>
            <iyz>-5.986609446803471e-14</iyz>
            <izz>1.0612370823759156e-09</izz>
          </inertia>
        </inertial>
        <collision name="link_7_collision">
          <pose>0.0 0.0 0.0 0.0 0.0 0.0</pose>
          <geometry>
            <mesh>
              <uri>meshes_salamander/link_7.obj</uri>
              <scale>0.1 0.1 0.1</scale>
            </mesh>
          </geometry>
        </collision>
        <visual name="link_7_visual">
          <pose>0.0 0.0 0.0 0.0 0.0 0.0</pose>
          <geometry>
            <mesh>
              <uri>meshes_salamander/link_7.obj</uri>
              <scale>0.1 0.1 0.1</scale>
            </mesh>
          </geometry>
          <material>
            <ambient>0.06999999999999999 0.48999999999999994 0.06999999999999999 1.0</ambient>
            <diffuse>0.06999999999999999 0.48999999999999994 0.06999999999999999 1.0</diffuse>
            <specular>0.06999999999999999 0.48999999999999994 0.06999999999999999 1.0</specular>
            <emissive>0.06999999999999999 0.48999999999999994 0.06999999999999999 1.0</emissive>
          </material>
        </visual>
      </link>
      <link name="link_body_8">
        <pose>0.08999999761581422 0.0 0.0 0.0 0.0 0.0</pose>
        <inertial>
          <pose>0.0031009513903408055 -3.8104457407535856e-07 -2.2183405479165574e-07 0.0 0.0 0.0</pose>
          <mass>6.504374491994881e-05</mass>
          <inertia>
            <ixx>1.2226978618918127e-10</ixx>
            <ixy>1.6420788448950181e-13</ixy>
            <ixz>-1.9110569761093235e-13</ixz>
            <iyy>5.157770720769804e-10</iyy>
            <iyz>-9.629863494304086e-14</iyz>
            <izz>4.3925506511082714e-10</izz>
          </inertia>
        </inertial>
        <collision name="link_8_collision">
          <pose>0.0 0.0 0.0 0.0 0.0 0.0</pose>
          <geometry>
            <mesh>
              <uri>meshes_salamander/link_8.obj</uri>
              <scale>0.1 0.1 0.1</scale>
            </mesh>
          </geometry>
        </collision>
        <visual name="link_8_visual">
          <pose>0.0 0.0 0.0 0.0 0.0 0.0</pose>
          <geometry>
            <mesh>
              <uri>meshes_salamander/link_8.obj</uri>
              <scale>0.1 0.1 0.1</scale>
            </mesh>
          </geometry>
          <material>
            <ambient>0.1 0.7 0.1 1.0</ambient>
            <diffuse>0.1 0.7 0.1 1.0</diffuse>
            <specular>0.1 0.7 0.1 1.0</specular>
            <emissive>0.1 0.7 0.1 1.0</emissive>
          </material>
        </visual>
      </link>
      <link name="link_leg_0_L_0">
        <pose>0.015000000596046448 -0.004 -0.002 0.0 0.0 0.0</pose>
        <collision name="link_leg_0_L_0_collision">
          <pose>0.0 0.0 0.0 0.0 0.0 0.0</pose>
          <geometry>
            <sphere>
              <radius>0.0011</radius>
            </sphere>
          </geometry>
        </collision>
        <visual name="link_leg_0_L_0_visual">
          <pose>0.0 0.0 0.0 0.0 0.0 0.0</pose>
          <geometry>
            <sphere>
              <radius>0.0011</radius>
            </sphere>
          </geometry>
          <material>
            <ambient>0.7 0.5 0.5 0.5</ambient>
            <diffuse>0.7 0.5 0.5 0.5</diffuse>
            <specular>0.7 0.5 0.5 0.5</specular>
            <emissive>0.7 0.5 0.5 0.5</emissive>
          </material>
        </visual>
      </link>
      <link name="link_leg_0_L_1">
        <pose>0.015000000596046448 -0.004 -0.002 0.0 0.0 0.0</pose>
        <collision name="link_leg_0_L_1_collision">
          <pose>0.0 0.0 0.0 0.0 0.0 0.0</pose>
          <geometry>
            <sphere>
              <radius>0.0013000000000000002</radius>
            </sphere>
          </geometry>
        </collision>
        <visual name="link_leg_0_L_1_visual">
          <pose>0.0 0.0 0.0 0.0 0.0 0.0</pose>
          <geometry>
            <sphere>
              <radius>0.0013000000000000002</radius>
            </sphere>
          </geometry>
          <material>
            <ambient>0.9 0.9 0.9 0.3</ambient>
            <diffuse>0.9 0.9 0.9 0.3</diffuse>
            <specular>0.9 0.9 0.9 0.3</specular>
            <emissive>0.9 0.9 0.9 0.3</emissive>
          </material>
        </visual>
      </link>
      <link name="link_leg_0_L_2">
        <pose>0.015000000596046448 -0.004 -0.002 0.0 0.0 0.0</pose>
        <inertial>
          <pose>0.0 -0.002 0.0 1.5707963267948966 0.0 0.0</pose>
          <mass>1.6755160819145562e-05</mass>
          <inertia>
            <ixx>2.652900463031381e-11</ixx>
            <ixy>0</ixy>
            <ixz>0</ixz>
            <iyy>2.652900463031381e-11</iyy>
            <iyz>0</iyz>
            <izz>8.37758040957278e-12</izz>
          </inertia>
        </inertial>
        <collision name="link_leg_0_L_2_collision">
          <pose>0 -0.002 0 1.5707963267948966 0 0</pose>
          <geometry>
            <capsule>
              <radius>0.001</radius>
              <length>0.004</length>
            </capsule>
          </geometry>
        </collision>
        <visual name="link_leg_0_L_2_visual">
          <pose>0 -0.002 0 1.5707963267948966 0 0</pose>
          <geometry>
            <capsule>
              <radius>0.001</radius>
              <length>0.004</length>
            </capsule>
          </geometry>
          <material/>
        </visual>
      </link>
      <link name="link_leg_0_L_3">
        <pose>0.015000000596046448 -0.008 -0.002 0.0 0.0 0.0</pose>
        <inertial>
          <pose>0.0 -0.002 0.0 1.5707963267948966 0.0 0.0</pose>
          <mass>1.6755160819145562e-05</mass>
          <inertia>
            <ixx>2.652900463031381e-11</ixx>
            <ixy>0</ixy>
            <ixz>0</ixz>
            <iyy>2.652900463031381e-11</iyy>
            <iyz>0</iyz>
            <izz>8.37758040957278e-12</izz>
          </inertia>
        </inertial>
        <collision name="link_leg_0_L_3_collision">
          <pose>0 -0.002 0 1.5707963267948966 0 0</pose>
          <geometry>
            <capsule>
              <radius>0.001</radius>
              <length>0.004</length>
            </capsule>
          </geometry>
        </collision>
        <visual name="link_leg_0_L_3_visual">
          <pose>0 -0.002 0 1.5707963267948966 0 0</pose>
          <geometry>
            <capsule>
              <radius>0.001</radius>
              <length>0.004</length>
            </capsule>
          </geometry>
          <material/>
        </visual>
      </link>
      <link name="link_leg_0_R_0">
        <pose>0.015000000596046448 0.004 -0.002 0.0 0.0 0.0</pose>
        <collision name="link_leg_0_R_0_collision">
          <pose>0.0 0.0 0.0 0.0 0.0 0.0</pose>
          <geometry>
            <sphere>
              <radius>0.0011</radius>
            </sphere>
          </geometry>
        </collision>
        <visual name="link_leg_0_R_0_visual">
          <pose>0.0 0.0 0.0 0.0 0.0 0.0</pose>
          <geometry>
            <sphere>
              <radius>0.0011</radius>
            </sphere>
          </geometry>
          <material>
            <ambient>0.7 0.5 0.5 0.5</ambient>
            <diffuse>0.7 0.5 0.5 0.5</diffuse>
            <specular>0.7 0.5 0.5 0.5</specular>
            <emissive>0.7 0.5 0.5 0.5</emissive>
          </material>
        </visual>
      </link>
      <link name="link_leg_0_R_1">
        <pose>0.015000000596046448 0.004 -0.002 0.0 0.0 0.0</pose>
        <collision name="link_leg_0_R_1_collision">
          <pose>0.0 0.0 0.0 0.0 0.0 0.0</pose>
          <geometry>
            <sphere>
              <radius>0.0013000000000000002</radius>
            </sphere>
          </geometry>
        </collision>
        <visual name="link_leg_0_R_1_visual">
          <pose>0.0 0.0 0.0 0.0 0.0 0.0</pose>
          <geometry>
            <sphere>
              <radius>0.0013000000000000002</radius>
            </sphere>
          </geometry>
          <material>
            <ambient>0.9 0.9 0.9 0.3</ambient>
            <diffuse>0.9 0.9 0.9 0.3</diffuse>
            <specular>0.9 0.9 0.9 0.3</specular>
            <emissive>0.9 0.9 0.9 0.3</emissive>
          </material>
        </visual>
      </link>
      <link name="link_leg_0_R_2">
        <pose>0.015000000596046448 0.004 -0.002 0.0 0.0 0.0</pose>
        <inertial>
          <pose>0.0 0.002 0.0 1.5707963267948966 0.0 0.0</pose>
          <mass>1.6755160819145562e-05</mass>
          <inertia>
            <ixx>2.652900463031381e-11</ixx>
            <ixy>0</ixy>
            <ixz>0</ixz>
            <iyy>2.652900463031381e-11</iyy>
            <iyz>0</iyz>
            <izz>8.37758040957278e-12</izz>
          </inertia>
        </inertial>
        <collision name="link_leg_0_R_2_collision">
          <pose>0 0.002 0 1.5707963267948966 0 0</pose>
          <geometry>
            <capsule>
              <radius>0.001</radius>
              <length>0.004</length>
            </capsule>
          </geometry>
        </collision>
        <visual name="link_leg_0_R_2_visual">
          <pose>0 0.002 0 1.5707963267948966 0 0</pose>
          <geometry>
            <capsule>
              <radius>0.001</radius>
              <length>0.004</length>
            </capsule>
          </geometry>
          <material/>
        </visual>
      </link>
      <link name="link_leg_0_R_3">
        <pose>0.015000000596046448 0.008 -0.002 0.0 0.0 0.0</pose>
        <inertial>
          <pose>0.0 0.002 0.0 1.5707963267948966 0.0 0.0</pose>
          <mass>1.6755160819145562e-05</mass>
          <inertia>
            <ixx>2.652900463031381e-11</ixx>
            <ixy>0</ixy>
            <ixz>0</ixz>
            <iyy>2.652900463031381e-11</iyy>
            <iyz>0</iyz>
            <izz>8.37758040957278e-12</izz>
          </inertia>
        </inertial>
        <collision name="link_leg_0_R_3_collision">
          <pose>0 0.002 0 1.5707963267948966 0 0</pose>
          <geometry>
            <capsule>
              <radius>0.001</radius>
              <length>0.004</length>
            </capsule>
          </geometry>
        </collision>
        <visual name="link_leg_0_R_3_visual">
          <pose>0 0.002 0 1.5707963267948966 0 0</pose>
          <geometry>
            <capsule>
              <radius>0.001</radius>
              <length>0.004</length>
            </capsule>
          </geometry>
          <material/>
        </visual>
      </link>
      <link name="link_leg_1_L_0">
        <pose>0.04614285731315613 -0.003 -0.002 0.0 0.0 0.0</pose>
        <collision name="link_leg_1_L_0_collision">
          <pose>0.0 0.0 0.0 0.0 0.0 0.0</pose>
          <geometry>
            <sphere>
              <radius>0.0011</radius>
            </sphere>
          </geometry>
        </collision>
        <visual name="link_leg_1_L_0_visual">
          <pose>0.0 0.0 0.0 0.0 0.0 0.0</pose>
          <geometry>
            <sphere>
              <radius>0.0011</radius>
            </sphere>
          </geometry>
          <material>
            <ambient>0.7 0.5 0.5 0.5</ambient>
            <diffuse>0.7 0.5 0.5 0.5</diffuse>
            <specular>0.7 0.5 0.5 0.5</specular>
            <emissive>0.7 0.5 0.5 0.5</emissive>
          </material>
        </visual>
      </link>
      <link name="link_leg_1_L_1">
        <pose>0.04614285731315613 -0.003 -0.002 0.0 0.0 0.0</pose>
        <collision name="link_leg_1_L_1_collision">
          <pose>0.0 0.0 0.0 0.0 0.0 0.0</pose>
          <geometry>
            <sphere>
              <radius>0.0013000000000000002</radius>
            </sphere>
          </geometry>
        </collision>
        <visual name="link_leg_1_L_1_visual">
          <pose>0.0 0.0 0.0 0.0 0.0 0.0</pose>
          <geometry>
            <sphere>
              <radius>0.0013000000000000002</radius>
            </sphere>
          </geometry>
          <material>
            <ambient>0.9 0.9 0.9 0.3</ambient>
            <diffuse>0.9 0.9 0.9 0.3</diffuse>
            <specular>0.9 0.9 0.9 0.3</specular>
            <emissive>0.9 0.9 0.9 0.3</emissive>
          </material>
        </visual>
      </link>
      <link name="link_leg_1_L_2">
        <pose>0.04614285731315613 -0.003 -0.002 0.0 0.0 0.0</pose>
        <inertial>
          <pose>0.0 -0.002 0.0 1.5707963267948966 0.0 0.0</pose>
          <mass>1.6755160819145562e-05</mass>
          <inertia>
            <ixx>2.652900463031381e-11</ixx>
            <ixy>0</ixy>
            <ixz>0</ixz>
            <iyy>2.652900463031381e-11</iyy>
            <iyz>0</iyz>
            <izz>8.37758040957278e-12</izz>
          </inertia>
        </inertial>
        <collision name="link_leg_1_L_2_collision">
          <pose>0 -0.002 0 1.5707963267948966 0 0</pose>
          <geometry>
            <capsule>
              <radius>0.001</radius>
              <length>0.004</length>
            </capsule>
          </geometry>
        </collision>
        <visual name="link_leg_1_L_2_visual">
          <pose>0 -0.002 0 1.5707963267948966 0 0</pose>
          <geometry>
            <capsule>
              <radius>0.001</radius>
              <length>0.004</length>
            </capsule>
          </geometry>
          <material/>
        </visual>
      </link>
      <link name="link_leg_1_L_3">
        <pose>0.04614285731315613 -0.007 -0.002 0.0 0.0 0.0</pose>
        <inertial>
          <pose>0.0 -0.002 0.0 1.5707963267948966 0.0 0.0</pose>
          <mass>1.6755160819145562e-05</mass>
          <inertia>
            <ixx>2.652900463031381e-11</ixx>
            <ixy>0</ixy>
            <ixz>0</ixz>
            <iyy>2.652900463031381e-11</iyy>
            <iyz>0</iyz>
            <izz>8.37758040957278e-12</izz>
          </inertia>
        </inertial>
        <collision name="link_leg_1_L_3_collision">
          <pose>0 -0.002 0 1.5707963267948966 0 0</pose>
          <geometry>
            <capsule>
              <radius>0.001</radius>
              <length>0.004</length>
            </capsule>
          </geometry>
        </collision>
        <visual name="link_leg_1_L_3_visual">
          <pose>0 -0.002 0 1.5707963267948966 0 0</pose>
          <geometry>
            <capsule>
              <radius>0.001</radius>
              <length>0.004</length>
            </capsule>
          </geometry>
          <material/>
        </visual>
      </link>
      <link name="link_leg_1_R_0">
        <pose>0.04614285731315613 0.003 -0.002 0.0 0.0 0.0</pose>
        <collision name="link_leg_1_R_0_collision">
          <pose>0.0 0.0 0.0 0.0 0.0 0.0</pose>
          <geometry>
            <sphere>
              <radius>0.0011</radius>
            </sphere>
          </geometry>
        </collision>
        <visual name="link_leg_1_R_0_visual">
          <pose>0.0 0.0 0.0 0.0 0.0 0.0</pose>
          <geometry>
            <sphere>
              <radius>0.0011</radius>
            </sphere>
          </geometry>
          <material>
            <ambient>0.7 0.5 0.5 0.5</ambient>
            <diffuse>0.7 0.5 0.5 0.5</diffuse>
            <specular>0.7 0.5 0.5 0.5</specular>
            <emissive>0.7 0.5 0.5 0.5</emissive>
          </material>
        </visual>
      </link>
      <link name="link_leg_1_R_1">
        <pose>0.04614285731315613 0.003 -0.002 0.0 0.0 0.0</pose>
        <collision name="link_leg_1_R_1_collision">
          <pose>0.0 0.0 0.0 0.0 0.0 0.0</pose>
          <geometry>
            <sphere>
              <radius>0.0013000000000000002</radius>
            </sphere>
          </geometry>
        </collision>
        <visual name="link_leg_1_R_1_visual">
          <pose>0.0 0.0 0.0 0.0 0.0 0.0</pose>
          <geometry>
            <sphere>
              <radius>0.0013000000000000002</radius>
            </sphere>
          </geometry>
          <material>
            <ambient>0.9 0.9 0.9 0.3</ambient>
            <diffuse>0.9 0.9 0.9 0.3</diffuse>
            <specular>0.9 0.9 0.9 0.3</specular>
            <emissive>0.9 0.9 0.9 0.3</emissive>
          </material>
        </visual>
      </link>
      <link name="link_leg_1_R_2">
        <pose>0.04614285731315613 0.003 -0.002 0.0 0.0 0.0</pose>
        <inertial>
          <pose>0.0 0.002 0.0 1.5707963267948966 0.0 0.0</pose>
          <mass>1.6755160819145562e-05</mass>
          <inertia>
            <ixx>2.652900463031381e-11</ixx>
            <ixy>0</ixy>
            <ixz>0</ixz>
            <iyy>2.652900463031381e-11</iyy>
            <iyz>0</iyz>
            <izz>8.37758040957278e-12</izz>
          </inertia>
        </inertial>
        <collision name="link_leg_1_R_2_collision">
          <pose>0 0.002 0 1.5707963267948966 0 0</pose>
          <geometry>
            <capsule>
              <radius>0.001</radius>
              <length>0.004</length>
            </capsule>
          </geometry>
        </collision>
        <visual name="link_leg_1_R_2_visual">
          <pose>0 0.002 0 1.5707963267948966 0 0</pose>
          <geometry>
            <capsule>
              <radius>0.001</radius>
              <length>0.004</length>
            </capsule>
          </geometry>
          <material/>
        </visual>
      </link>
      <link name="link_leg_1_R_3">
        <pose>0.04614285731315613 0.007 -0.002 0.0 0.0 0.0</pose>
        <inertial>
          <pose>0.0 0.002 0.0 1.5707963267948966 0.0 0.0</pose>
          <mass>1.6755160819145562e-05</mass>
          <inertia>
            <ixx>2.652900463031381e-11</ixx>
            <ixy>0</ixy>
            <ixz>0</ixz>
            <iyy>2.652900463031381e-11</iyy>
            <iyz>0</iyz>
            <izz>8.37758040957278e-12</izz>
          </inertia>
        </inertial>
        <collision name="link_leg_1_R_3_collision">
          <pose>0 0.002 0 1.5707963267948966 0 0</pose>
          <geometry>
            <capsule>
              <radius>0.001</radius>
              <length>0.004</length>
            </capsule>
          </geometry>
        </collision>
        <visual name="link_leg_1_R_3_visual">
          <pose>0 0.002 0 1.5707963267948966 0 0</pose>
          <geometry>
            <capsule>
              <radius>0.001</radius>
              <length>0.004</length>
            </capsule>
          </geometry>
          <material/>
        </visual>
      </link>
      <link name="foot_0_0">
        <pose>0.015000000596046448 -0.013000000000000001 -0.002 0.0 0.0 0.0</pose>
      </link>
      <link name="foot_0_1">
        <pose>0.015000000596046448 0.013000000000000001 -0.002 0.0 0.0 0.0</pose>
      </link>
      <link name="foot_1_0">
        <pose>0.04614285731315613 -0.012 -0.002 0.0 0.0 0.0</pose>
      </link>
      <link name="foot_1_1">
        <pose>0.04614285731315613 0.012 -0.002 0.0 0.0 0.0</pose>
      </link>
      <link name="link_passive_0">
        <pose>0.02571428716182709 0.0 0.0 0.0 0.0 0.0</pose>
      </link>
      <link name="link_passive_1">
        <pose>0.04714285731315613 0.0 0.0 0.0 0.0 0.0</pose>
      </link>
      <link name="link_passive_2">
        <pose>0.05785714387893677 0.0 0.0 0.0 0.0 0.0</pose>
      </link>
      <link name="link_passive_3">
        <pose>0.0685714304447174 0.0 0.0 0.0 0.0 0.0</pose>
      </link>
      <link name="link_passive_4">
        <pose>0.07928571701049805 0.0 0.0 0.0 0.0 0.0</pose>
      </link>
      <link name="link_passive_5">
        <pose>0.08999999761581422 0.0 0.0 0.0 0.0 0.0</pose>
      </link>
      <joint name="joint_body_0" type="revolute">
        <parent>link_body_0</parent>
        <child>link_body_1</child>
        <pose>0.0 0.0 0.0 0.0 0.0 0.0</pose>
        <axis>
          <xyz>0.0 0.0 1.0</xyz>
          <limit>
            <lower>-1.5707963267948966</lower>
            <upper>1.5707963267948966</upper>
            <effort>inf</effort>
            <velocity>inf</velocity>
          </limit>
        </axis>
      </joint>
      <joint name="joint_body_1" type="revolute">
        <parent>link_passive_0</parent>
        <child>link_body_2</child>
        <pose>0.0 0.0 0.0 0.0 0.0 0.0</pose>
        <axis>
          <xyz>0.0 0.0 1.0</xyz>
          <limit>
            <lower>-1.5707963267948966</lower>
            <upper>1.5707963267948966</upper>
            <effort>inf</effort>
            <velocity>inf</velocity>
          </limit>
        </axis>
      </joint>
      <joint name="joint_body_2" type="revolute">
        <parent>link_body_2</parent>
        <child>link_body_3</child>
        <pose>0.0 0.0 0.0 0.0 0.0 0.0</pose>
        <axis>
          <xyz>0.0 0.0 1.0</xyz>
          <limit>
            <lower>-1.5707963267948966</lower>
            <upper>1.5707963267948966</upper>
            <effort>inf</effort>
            <velocity>inf</velocity>
          </limit>
        </axis>
      </joint>
      <joint name="joint_body_3" type="revolute">
        <parent>link_passive_1</parent>
        <child>link_body_4</child>
        <pose>0.0 0.0 0.0 0.0 0.0 0.0</pose>
        <axis>
          <xyz>0.0 0.0 1.0</xyz>
          <limit>
            <lower>-1.5707963267948966</lower>
            <upper>1.5707963267948966</upper>
            <effort>inf</effort>
            <velocity>inf</velocity>
          </limit>
        </axis>
      </joint>
      <joint name="joint_body_4" type="revolute">
        <parent>link_passive_2</parent>
        <child>link_body_5</child>
        <pose>0.0 0.0 0.0 0.0 0.0 0.0</pose>
        <axis>
          <xyz>0.0 0.0 1.0</xyz>
          <limit>
            <lower>-1.5707963267948966</lower>
            <upper>1.5707963267948966</upper>
            <effort>inf</effort>
            <velocity>inf</velocity>
          </limit>
        </axis>
      </joint>
      <joint name="joint_body_5" type="revolute">
        <parent>link_passive_3</parent>
        <child>link_body_6</child>
        <pose>0.0 0.0 0.0 0.0 0.0 0.0</pose>
        <axis>
          <xyz>0.0 0.0 1.0</xyz>
          <limit>
            <lower>-1.5707963267948966</lower>
            <upper>1.5707963267948966</upper>
            <effort>inf</effort>
            <velocity>inf</velocity>
          </limit>
        </axis>
      </joint>
      <joint name="joint_body_6" type="revolute">
        <parent>link_passive_4</parent>
        <child>link_body_7</child>
        <pose>0.0 0.0 0.0 0.0 0.0 0.0</pose>
        <axis>
          <xyz>0.0 0.0 1.0</xyz>
          <limit>
            <lower>-1.5707963267948966</lower>
            <upper>1.5707963267948966</upper>
            <effort>inf</effort>
            <velocity>inf</velocity>
          </limit>
        </axis>
      </joint>
      <joint name="joint_body_7" type="revolute">
        <parent>link_passive_5</parent>
        <child>link_body_8</child>
        <pose>0.0 0.0 0.0 0.0 0.0 0.0</pose>
        <axis>
          <xyz>0.0 0.0 1.0</xyz>
          <limit>
            <lower>-1.5707963267948966</lower>
            <upper>1.5707963267948966</upper>
            <effort>inf</effort>
            <velocity>inf</velocity>
          </limit>
        </axis>
      </joint>
      <joint name="joint_leg_0_L_0" type="revolute">
        <parent>link_body_1</parent>
        <child>link_leg_0_L_0</child>
        <pose>0.0 0.0 0.0 0.0 0.0 0.0</pose>
        <axis>
          <xyz>0 0 -1</xyz>
          <limit>
            <lower>-3.141592653589793</lower>
            <upper>3.141592653589793</upper>
            <effort>inf</effort>
            <velocity>inf</velocity>
          </limit>
        </axis>
      </joint>
      <joint name="joint_leg_0_L_1" type="revolute">
        <parent>link_leg_0_L_0</parent>
        <child>link_leg_0_L_1</child>
        <pose>0.0 0.0 0.0 0.0 0.0 0.0</pose>
        <axis>
          <xyz>1 0 0</xyz>
          <limit>
            <lower>-3.141592653589793</lower>
            <upper>3.141592653589793</upper>
            <effort>inf</effort>
            <velocity>inf</velocity>
          </limit>
        </axis>
      </joint>
      <joint name="joint_leg_0_L_2" type="revolute">
        <parent>link_leg_0_L_1</parent>
        <child>link_leg_0_L_2</child>
        <pose>0.0 0.0 0.0 0.0 0.0 0.0</pose>
        <axis>
          <xyz>0 1 0</xyz>
          <limit>
            <lower>-3.141592653589793</lower>
            <upper>3.141592653589793</upper>
            <effort>inf</effort>
            <velocity>inf</velocity>
          </limit>
        </axis>
      </joint>
      <joint name="joint_leg_0_L_3" type="revolute">
        <parent>link_leg_0_L_2</parent>
        <child>link_leg_0_L_3</child>
        <pose>0.0 0.0 0.0 0.0 0.0 0.0</pose>
        <axis>
          <xyz>1 0 0</xyz>
          <limit>
            <lower>-3.141592653589793</lower>
            <upper>3.141592653589793</upper>
            <effort>inf</effort>
            <velocity>inf</velocity>
          </limit>
        </axis>
      </joint>
      <joint name="joint_leg_0_R_0" type="revolute">
        <parent>link_body_1</parent>
        <child>link_leg_0_R_0</child>
        <pose>0.0 0.0 0.0 0.0 0.0 0.0</pose>
        <axis>
          <xyz>0 0 1</xyz>
          <limit>
            <lower>-3.141592653589793</lower>
            <upper>3.141592653589793</upper>
            <effort>inf</effort>
            <velocity>inf</velocity>
          </limit>
        </axis>
      </joint>
      <joint name="joint_leg_0_R_1" type="revolute">
        <parent>link_leg_0_R_0</parent>
        <child>link_leg_0_R_1</child>
        <pose>0.0 0.0 0.0 0.0 0.0 0.0</pose>
        <axis>
          <xyz>-1 0 0</xyz>
          <limit>
            <lower>-3.141592653589793</lower>
            <upper>3.141592653589793</upper>
            <effort>inf</effort>
            <velocity>inf</velocity>
          </limit>
        </axis>
      </joint>
      <joint name="joint_leg_0_R_2" type="revolute">
        <parent>link_leg_0_R_1</parent>
        <child>link_leg_0_R_2</child>
        <pose>0.0 0.0 0.0 0.0 0.0 0.0</pose>
        <axis>
          <xyz>0 1 0</xyz>
          <limit>
            <lower>-3.141592653589793</lower>
            <upper>3.141592653589793</upper>
            <effort>inf</effort>
            <velocity>inf</velocity>
          </limit>
        </axis>
      </joint>
      <joint name="joint_leg_0_R_3" type="revolute">
        <parent>link_leg_0_R_2</parent>
        <child>link_leg_0_R_3</child>
        <pose>0.0 0.0 0.0 0.0 0.0 0.0</pose>
        <axis>
          <xyz>-1 0 0</xyz>
          <limit>
            <lower>-3.141592653589793</lower>
            <upper>3.141592653589793</upper>
            <effort>inf</effort>
            <velocity>inf</velocity>
          </limit>
        </axis>
      </joint>
      <joint name="joint_leg_1_L_0" type="revolute">
        <parent>link_body_4</parent>
        <child>link_leg_1_L_0</child>
        <pose>0.0 0.0 0.0 0.0 0.0 0.0</pose>
        <axis>
          <xyz>0 0 -1</xyz>
          <limit>
            <lower>-3.141592653589793</lower>
            <upper>3.141592653589793</upper>
            <effort>inf</effort>
            <velocity>inf</velocity>
          </limit>
        </axis>
      </joint>
      <joint name="joint_leg_1_L_1" type="revolute">
        <parent>link_leg_1_L_0</parent>
        <child>link_leg_1_L_1</child>
        <pose>0.0 0.0 0.0 0.0 0.0 0.0</pose>
        <axis>
          <xyz>1 0 0</xyz>
          <limit>
            <lower>-3.141592653589793</lower>
            <upper>3.141592653589793</upper>
            <effort>inf</effort>
            <velocity>inf</velocity>
          </limit>
        </axis>
      </joint>
      <joint name="joint_leg_1_L_2" type="revolute">
        <parent>link_leg_1_L_1</parent>
        <child>link_leg_1_L_2</child>
        <pose>0.0 0.0 0.0 0.0 0.0 0.0</pose>
        <axis>
          <xyz>0 1 0</xyz>
          <limit>
            <lower>-3.141592653589793</lower>
            <upper>3.141592653589793</upper>
            <effort>inf</effort>
            <velocity>inf</velocity>
          </limit>
        </axis>
      </joint>
      <joint name="joint_leg_1_L_3" type="revolute">
        <parent>link_leg_1_L_2</parent>
        <child>link_leg_1_L_3</child>
        <pose>0.0 0.0 0.0 0.0 0.0 0.0</pose>
        <axis>
          <xyz>1 0 0</xyz>
          <limit>
            <lower>-3.141592653589793</lower>
            <upper>3.141592653589793</upper>
            <effort>inf</effort>
            <velocity>inf</velocity>
          </limit>
        </axis>
      </joint>
      <joint name="joint_leg_1_R_0" type="revolute">
        <parent>link_body_4</parent>
        <child>link_leg_1_R_0</child>
        <pose>0.0 0.0 0.0 0.0 0.0 0.0</pose>
        <axis>
          <xyz>0 0 1</xyz>
          <limit>
            <lower>-3.141592653589793</lower>
            <upper>3.141592653589793</upper>
            <effort>inf</effort>
            <velocity>inf</velocity>
          </limit>
        </axis>
      </joint>
      <joint name="joint_leg_1_R_1" type="revolute">
        <parent>link_leg_1_R_0</parent>
        <child>link_leg_1_R_1</child>
        <pose>0.0 0.0 0.0 0.0 0.0 0.0</pose>
        <axis>
          <xyz>-1 0 0</xyz>
          <limit>
            <lower>-3.141592653589793</lower>
            <upper>3.141592653589793</upper>
            <effort>inf</effort>
            <velocity>inf</velocity>
          </limit>
        </axis>
      </joint>
      <joint name="joint_leg_1_R_2" type="revolute">
        <parent>link_leg_1_R_1</parent>
        <child>link_leg_1_R_2</child>
        <pose>0.0 0.0 0.0 0.0 0.0 0.0</pose>
        <axis>
          <xyz>0 1 0</xyz>
          <limit>
            <lower>-3.141592653589793</lower>
            <upper>3.141592653589793</upper>
            <effort>inf</effort>
            <velocity>inf</velocity>
          </limit>
        </axis>
      </joint>
      <joint name="joint_leg_1_R_3" type="revolute">
        <parent>link_leg_1_R_2</parent>
        <child>link_leg_1_R_3</child>
        <pose>0.0 0.0 0.0 0.0 0.0 0.0</pose>
        <axis>
          <xyz>-1 0 0</xyz>
          <limit>
            <lower>-3.141592653589793</lower>
            <upper>3.141592653589793</upper>
            <effort>inf</effort>
            <velocity>inf</velocity>
          </limit>
        </axis>
      </joint>
      <joint name="joint_foot_0_0" type="fixed">
        <parent>link_leg_0_L_3</parent>
        <child>foot_0_0</child>
        <pose>0.0 0.0 0.0 0.0 0.0 0.0</pose>
      </joint>
      <joint name="joint_foot_0_1" type="fixed">
        <parent>link_leg_0_R_3</parent>
        <child>foot_0_1</child>
        <pose>0.0 0.0 0.0 0.0 0.0 0.0</pose>
      </joint>
      <joint name="joint_foot_1_0" type="fixed">
        <parent>link_leg_1_L_3</parent>
        <child>foot_1_0</child>
        <pose>0.0 0.0 0.0 0.0 0.0 0.0</pose>
      </joint>
      <joint name="joint_foot_1_1" type="fixed">
        <parent>link_leg_1_R_3</parent>
        <child>foot_1_1</child>
        <pose>0.0 0.0 0.0 0.0 0.0 0.0</pose>
      </joint>
      <joint name="joint_passive_0" type="revolute">
        <parent>link_body_1</parent>
        <child>link_passive_0</child>
        <pose>0 0 0 0 0 0</pose>
        <axis>
          <xyz>0 1 0</xyz>
          <limit>
            <lower>-1.5707963267948966</lower>
            <upper>1.5707963267948966</upper>
            <effort>inf</effort>
            <velocity>inf</velocity>
          </limit>
        </axis>
      </joint>
      <joint name="joint_passive_1" type="revolute">
        <parent>link_body_3</parent>
        <child>link_passive_1</child>
        <pose>0 0 0 0 0 0</pose>
        <axis>
          <xyz>0 1 0</xyz>
          <limit>
            <lower>-1.5707963267948966</lower>
            <upper>1.5707963267948966</upper>
            <effort>inf</effort>
            <velocity>inf</velocity>
          </limit>
        </axis>
      </joint>
      <joint name="joint_passive_2" type="revolute">
        <parent>link_body_4</parent>
        <child>link_passive_2</child>
        <pose>0 0 0 0 0 0</pose>
        <axis>
          <xyz>0 1 0</xyz>
          <limit>
            <lower>-1.5707963267948966</lower>
            <upper>1.5707963267948966</upper>
            <effort>inf</effort>
            <velocity>inf</velocity>
          </limit>
        </axis>
      </joint>
      <joint name="joint_passive_3" type="revolute">
        <parent>link_body_5</parent>
        <child>link_passive_3</child>
        <pose>0 0 0 0 0 0</pose>
        <axis>
          <xyz>0 1 0</xyz>
          <limit>
            <lower>-1.5707963267948966</lower>
            <upper>1.5707963267948966</upper>
            <effort>inf</effort>
            <velocity>inf</velocity>
          </limit>
        </axis>
      </joint>
      <joint name="joint_passive_4" type="revolute">
        <parent>link_body_6</parent>
        <child>link_passive_4</child>
        <pose>0 0 0 0 0 0</pose>
        <axis>
          <xyz>0 1 0</xyz>
          <limit>
            <lower>-1.5707963267948966</lower>
            <upper>1.5707963267948966</upper>
            <effort>inf</effort>
            <velocity>inf</velocity>
          </limit>
        </axis>
      </joint>
      <joint name="joint_passive_5" type="revolute">
        <parent>link_body_7</parent>
        <child>link_passive_5</child>
        <pose>0 0 0 0 0 0</pose>
        <axis>
          <xyz>0 1 0</xyz>
          <limit>
            <lower>-1.5707963267948966</lower>
            <upper>1.5707963267948966</upper>
            <effort>inf</effort>
            <velocity>inf</velocity>
          </limit>
        </axis>
      </joint>
    </model>
  </world>
</sdf>
